Workbook
Name ApprovalDate: #REF!
Name ApprovedByPerson: #REF!
Name Copyright: #REF!
Name DocumentId: #REF!
Name DocumentKind: #REF!
Name DocumentRevisionId: #REF!
Name DocumentTitle: #REF!
Name LanguageCode: #REF!
Name LifecycleStatus: #REF!
Name OwningOrganization: #REF!
Name PreparedByPerson: #REF!
Name PreparedDate: #REF!
Name SecurityLevel: #REF!

Sheet Informationen
C2: Line | E2: Trafo | G2: Trafo Berechnung | J2: Allgemin | Q2: Kabel Berechnung
A3: Core Nr. | B3: Nr. | C3: Ikmax | D3: Itmax | E3: Irt | F3: Itf | G3: TMVA | H3: Un | I3: Zt | J3: Ipr | K3: Isr | L3: ALF | M3: Rl | N3: Rct | O3: Sr | P3: Sn | Q3: cabel length | R3: cable diameter | S3: max Temperatur
A4: 1 | B4: 1 | C4: 50 | D4: 50 | E4: 0.5 | F4: 2 | G4: 220 | H4: 220 | I4: 23 | J4: 800 | K4: 1 | L4: 20 | M4: =0.0175*Tabelle22[[#This Row],[cabel length]]/Tabelle22[[#This Row],[cable diameter]]*(1+0.00393*(Tabelle22[[#This Row],[max Temperatur]]-20)) -> 0.47885906 | N4: 7 | O4: 0.02 | P4: 30 | Q4: 90 | R4: 4 | S4: 75
A5: 1 | B5: 4 | C5: 6.6 | D5: 50 | E5: 1.2 | F5: 6.6 | G5: 310 | H5: 150 | I5: 18 | J5: 1250 | K5: 1 | L5: 20 | M5: =0.0175*Tabelle22[[#This Row],[cabel length]]/Tabelle22[[#This Row],[cable diameter]]*(1+0.00393*(Tabelle22[[#This Row],[max Temperatur]]-20)) -> 0.34584266 | N5: 7 | O5: 0.02 | P5: 10 | Q5: 65 | R5: 4 | S5: 75
A6: 2 | B6: 5 | C6: 29 | D6: 40 | E6: 1.25 | F6: 29 | G6: 325 | H6: 150 | I6: 5 | J6: 1250 | K6: 1 | L6: 20 | M6: =0.0175*Tabelle22[[#This Row],[cabel length]]/Tabelle22[[#This Row],[cable diameter]]*(1+0.00393*(Tabelle22[[#This Row],[max Temperatur]]-20)) -> 0.34584266 | N6: 7 | O6: 0.02 | P6: 10 | Q6: 65 | R6: 4 | S6: 75
A7: 3 | B7: 7 | C7: 40 | D7: 40 | E7: 1.193 | F7: 8 | G7: 310 | H7: 150 | I7: 18 | J7: 1250 | K7: 1 | L7: 20 | M7: =0.0175*Tabelle22[[#This Row],[cabel length]]/Tabelle22[[#This Row],[cable diameter]]*(1+0.00393*(Tabelle22[[#This Row],[max Temperatur]]-20)) -> 0.39904922 | N7: 7.5 | O7: 0.02 | P7: 30 | Q7: 75 | R7: 4 | S7: 75
A8: 4 | B8: 10 | C8: 40 | D8: 40 | E8: 0.8 | F8: 6 | G8: 200 | H8: 150 | I8: 15 | J8: 1600 | K8: 1 | L8: 40 | M8: =0.0175*Tabelle22[[#This Row],[cabel length]]/Tabelle22[[#This Row],[cable diameter]]*(1+0.00393*(Tabelle22[[#This Row],[max Temperatur]]-20)) -> 0.37244594 | N8: 7.5 | O8: 0.02 | P8: 10 | Q8: 70 | R8: 4 | S8: 75
A9: 1 | B9: 2 | C9: 31.5 | D9: 31.5 | E9: 2 | F9: 16 | G9: 110 | H9: 33 | I9: 12 | J9: 2500 | K9: 1 | L9: 20 | M9: =0.0175*Tabelle22[[#This Row],[cabel length]]/Tabelle22[[#This Row],[cable diameter]]*(1+0.00393*(Tabelle22[[#This Row],[max Temperatur]]-20)) -> 0.18444942 | N9: 14 | O9: 0.02 | P9: 15 | Q9: 13 | R9: 1.5 | S9: 75
A10: 2 | B10: 3 | C10: 40 | D10: 40 | E10: 2.7 | F10: 29 | G10: 175 | H10: 33 | I10: 12 | J10: 3000 | K10: 1 | L10: 60 | M10: =0.0175*Tabelle22[[#This Row],[cabel length]]/Tabelle22[[#This Row],[cable diameter]]*(1+0.00393*(Tabelle22[[#This Row],[max Temperatur]]-20)) -> 0.58527219 | N10: 20 | O10: 0.02 | P10: 30 | Q10: 110 | R10: 4 | S10: 75
A11: 3 | B11: 6 | C11: 29 | D11: 30 | E11: 2.7 | F11: 25 | G11: 155 | H11: 33 | I11: 12 | J11: 2500 | K11: 1 | L11: 20 | M11: =0.0175*Tabelle22[[#This Row],[cabel length]]/Tabelle22[[#This Row],[cable diameter]]*(1+0.00393*(Tabelle22[[#This Row],[max Temperatur]]-20)) -> 0.29263609 | N11: 14 | O11: 0.02 | P11: 20 | Q11: 55 | R11: 4 | S11: 75
A12: 4 | B12: 8 | C12: 29 | D12: 29 | E12: 2.712 | F12: 25 | G12: 155 | H12: 33 | I12: 10 | J12: 3000 | K12: 1 | L12: 20 | M12: =0.0175*Tabelle22[[#This Row],[cabel length]]/Tabelle22[[#This Row],[cable diameter]]*(1+0.00393*(Tabelle22[[#This Row],[max Temperatur]]-20)) -> 0.4256525 | N12: 18 | O12: 0.02 | P12: 20 | Q12: 80 | R12: 4 | S12: 75
A13: 5 | B13: 9 | C13: 8.4 | D13: 8.4 | E13: 0.5 | F13: 6 | G13: 30 | H13: 33 | I13: 8 | J13: 500 | K13: 1 | L13: 20 | M13: =0.0175*Tabelle22[[#This Row],[cabel length]]/Tabelle22[[#This Row],[cable diameter]]*(1+0.00393*(Tabelle22[[#This Row],[max Temperatur]]-20)) -> 0.340522 | N13: 2 | O13: 0.02 | P13: 10 | Q13: 40 | R13: 2.5 | S13: 75

Sheet Over Current
B1: 220 kV - Core 1
B2: General parameters
B3: Cable length | C3: 90 | D3: m
B4: Cable cross-section | C4: 4 | D4: mm²
B5: Maximum temperature | C5: 75 | D5: °C
B6: CT secondary resistance Rct | C6: 14 | D6: Ohm
B7: CT rated primary current Ipr | C7: 2500 | D7: A
B8: CT rated secondary current Isr | C8: 1 | D8: A
B9: IED input burden SR | C9: 0.02 | D9: VA
B10: Accuracy limiting factor ALF | C10: 20
B11: Rated CT output Sn | C11: 30 | D11: VA
B12: Intermediate calculations
B13: Total secondary burden | C13: =2*(0.0175*(C3/C4)*(1+0.00393*(C5-20)))+C6+(C9/C8^2) -> 14.977718 | D13: Ohm
B14: Available CT Eal | C14: =C10*C8*(C6+C11/C8^2) -> 880 | D14: V
B17: REF650 Over Current Calculation
B18: Inputs
B19: The primary operate value | C19: 1000 | D19: A
B20: Maximum close-in fault current | C20: 31500 | D20: A
B21: Results
B22: Criterion 1: Ealreq equation 336 | C22: =20*C19*C8/C7*(C6+C11/C8^2) -> 352 | D22: V
B23: Criterion 2: Ealreq equation 337 | C23: =C20*C8/C7*(C6+C11/C8^2) -> 554.4 | D23: V
B24: Required Eal | C24: =MAX(C22:C23) -> 554.4 | D24: V
B25: Pass / fail | C25: =IF(C24>C14,"fail","pass") -> pass
B28: REF630 Over Current Calculation
B29: Results
B30: Actual burden of the current transformer | C30: =C8^2*2*(0.0175*(C3/C4)*(1+0.00393*(C5-20)))+C9 -> 0.97771813 | D30: VA
B31: Approximate value of the accuracy limit factor | C31: =C10*(C8^2*C6+C11)/(C8^2*C6+C30) -> 58.753943
B32: Reqierd ALF | C32: =20*C19/C7 -> 8
B33: Pass / fail | C33: =IF(C31>C32,IF(C10>C30,"pass","fail"),"fail") -> pass

Sheet 220 - 1
B1: 220 kV - Core 1
B2: General parameters
B3: Cable length | C3: =Informationen!Q4 -> 90 | D3: m
B4: Cable cross-section | C4: =Informationen!R4 -> 4 | D4: mm²
B5: Maximum temperature | C5: =Informationen!S4 -> 75 | D5: °C
B6: CT secondary resistance Rct | C6: =Informationen!N4 -> 7 | D6: Ohm
B7: CT rated primary current Ipr | C7: =Informationen!J4 -> 800 | D7: A
B8: CT rated secondary current Isr | C8: =Informationen!K4 -> 1 | D8: A
B9: IED input burden SR | C9: =Informationen!O4 -> 0.02 | D9: VA
B10: Accuracy limiting factor ALF | C10: =Informationen!L4 -> 20
B11: Rated CT output Sn | C11: =Informationen!P4 -> 30 | D11: VA
B12: Intermediate calculations
B13: Total secondary burden | C13: =2*(0.0175*(C3/C4)*(1+0.00393*(C5-20)))+C6+(C9/C8^2) -> 7.9777181 | D13: Ohm
B14: Available CT Eal | C14: =C10*C8*(C6+C11/C8^2) -> 740 | D14: V
B17: RET670 - CT Requirement for Transformer Differential Protection
B18: Inputs
B19: Transformer Rating St | C19: =Informationen!G4 -> 220 | D19: MVA
B20: Nominal system voltage | C20: =Informationen!H4 -> 220 | D20: kV
B21: Transformer impedance | C21: =Informationen!I4 -> 23 | D21: %
B22: Current bypassing the transformer If | C22: 54654184 | D22: A
B23: Intermediate calculations
B24: Transformer rated primary current Irt | C24: =C19*1000/(C20*SQRT(3)) -> 577.35027 | D24: A
B25: Max. current through two main CTs and transformer Itf | C25: =C24*100/C21 -> 2510.2186 | D25: A
B26: Results
B27: Ealreq criterion 1: transformer rated current | C27: =30*C24*(C8/C7)*C13 -> 172.72266 | D27: V
B28: Ealreq criterion 2: through-fault current | C28: =2*C25*(C8/C7)*C13 -> 50.06454 | D28: V
B29: Required Eal | C29: =MAX(C27:C28) -> 172.72266 | D29: V
B30: Pass / fail | C30: =IF(C29>C14,"fail","pass") -> pass
B33: RED670 - CT Requirement for Line Differential Protection
B34: Inputs
B35: Maximum internal close-in fault current Ikmax | C35: =Informationen!C4*1000 -> 50000 | D35: A
B36: Maximum external through-fault current Itmax | C36: =Informationen!D4*1000 -> 50000 | D36: A
B37: Results
B38: Ealreq equation 601: internal close-in fault | C38: =C35*C13*(C8/C7) -> 498.60738 | D38: V
B39: Ealreq equation 602: external through-fault | C39: =2*C36*C13*(C8/C7) -> 997.21477 | D39: V
B40: Required Eal | C40: =MAX(C38:C39) -> 997.21477 | D40: V
B41: Pass / fail | C41: =IF(C40>C14,"fail","pass") -> fail

Sheet 150 - 1
B1: =TEXT(Informationen!H5,"0")&" kV - Core "&TEXT(Informationen!A5,"0") -> 150 kV - Core 1
B2: General parameters
B3: Cable length | C3: =Informationen!Q5 -> 65 | D3: m
B4: Cable cross-section | C4: =Informationen!R5 -> 4 | D4: mm²
B5: Maximum temperature | C5: =Informationen!S5 -> 75 | D5: °C
B6: CT secondary resistance Rct | C6: =Informationen!N5 -> 7 | D6: Ohm
B7: CT rated primary current Ipr | C7: =Informationen!J5 -> 1250 | D7: A
B8: CT rated secondary current Isr | C8: =Informationen!K5 -> 1 | D8: A
B9: IED input burden SR | C9: =Informationen!O5 -> 0.02 | D9: VA
B10: Accuracy limiting factor ALF | C10: =Informationen!L5 -> 20
B11: Rated CT output Sn | C11: =Informationen!P5 -> 10 | D11: VA
B12: Intermediate calculations
B13: Total secondary burden | C13: =2*(0.0175*(C3/C4)*(1+0.00393*(C5-20)))+C6+(C9/C8^2) -> 7.7116853 | D13: Ohm
B14: Available CT Eal | C14: =C10*C8*(C6+C11/C8^2) -> 340 | D14: V
B17: RET670 - CT Requirement for Transformer Differential Protection
B18: Inputs
B19: Transformer Rating St | C19: =Informationen!G5 -> 310 | D19: MVA
B20: Nominal system voltage | C20: =Informationen!H5 -> 150 | D20: kV
B21: Transformer impedance | C21: =Informationen!I5 -> 18 | D21: %
B22: Current bypassing the transformer If | C22: =Informationen!F5 -> 6.6 | D22: A
B23: Intermediate calculations
B24: Transformer rated primary current Irt | C24: =C19*1000/(C20*SQRT(3)) -> 1193.1906 | D24: A
B25: Max. current through two main CTs and transformer Itf | C25: =C24*100/C21 -> 6628.8364 | D25: A
B26: Results
B27: Ealreq criterion 1: transformer rated current | C27: =30*C24*(C8/C7)*C13 -> 220.83624 | D27: V
B28: Ealreq criterion 2: through-fault current | C28: =2*C25*(C8/C7)*C13 -> 81.791201 | D28: V
B29: Required Eal | C29: =MAX(C27:C28) -> 220.83624 | D29: V
B30: Pass / fail | C30: =IF(C29>C14,"fail","pass") -> pass
B33: RED670 - CT Requirement for Line Differential Protection
B34: Inputs
B35: Maximum internal close-in fault current Ikmax | C35: =Informationen!C5*1000 -> 6600 | D35: A
B36: Maximum external through-fault current Itmax | C36: =Informationen!D5*1000 -> 50000 | D36: A
B37: Results
B38: Ealreq equation 601: internal close-in fault | C38: =C35*C13*(C8/C7) -> 40.717698 | D38: V
B39: Ealreq equation 602: external through-fault | C39: =2*C36*C13*(C8/C7) -> 616.93482 | D39: V
B40: Required Eal | C40: =MAX(C38:C39) -> 616.93482 | D40: V
B41: Pass / fail | C41: =IF(C40>C14,"fail","pass") -> fail

Sheet 150 - 2
B1: =TEXT(Informationen!H6,"0")&" kV - Core "&TEXT(Informationen!A6,"0") -> 150 kV - Core 2
B2: General parameters
B3: Cable length | C3: =Informationen!Q6 -> 65 | D3: m
B4: Cable cross-section | C4: =Informationen!R6 -> 4 | D4: mm²
B5: Maximum temperature | C5: =Informationen!S6 -> 75 | D5: °C
B6: CT secondary resistance Rct | C6: =Informationen!N6 -> 7 | D6: Ohm
B7: CT rated primary current Ipr | C7: =Informationen!J6 -> 1250 | D7: A
B8: CT rated secondary current Isr | C8: =Informationen!K6 -> 1 | D8: A
B9: IED input burden SR | C9: =Informationen!O6 -> 0.02 | D9: VA
B10: Accuracy limiting factor ALF | C10: =Informationen!L6 -> 20
B11: Rated CT output Sn | C11: =Informationen!P6 -> 10 | D11: VA
B12: Intermediate calculations
B13: Total secondary burden | C13: =2*(0.0175*(C3/C4)*(1+0.00393*(C5-20)))+C6+(C9/C8^2) -> 7.7116853 | D13: Ohm
B14: Available CT Eal | C14: =C10*C8*(C6+C11/C8^2) -> 340 | D14: V
B17: RET670 - CT Requirement for Transformer Differential Protection
B18: Inputs
B19: Transformer Rating St | C19: =Informationen!G6 -> 325 | D19: MVA
B20: Nominal system voltage | C20: =Informationen!H6 -> 150 | D20: kV
B21: Transformer impedance | C21: =Informationen!I6 -> 5 | D21: %
B22: Current bypassing the transformer If | C22: =Informationen!F6 -> 29 | D22: A
B23: Intermediate calculations
B24: Transformer rated primary current Irt | C24: =C19*1000/(C20*SQRT(3)) -> 1250.9256 | D24: A
B25: Max. current through two main CTs and transformer Itf | C25: =C24*100/C21 -> 25018.512 | D25: A
B26: Results
B27: Ealreq criterion 1: transformer rated current | C27: =30*C24*(C8/C7)*C13 -> 231.52187 | D27: V
B28: Ealreq criterion 2: through-fault current | C28: =2*C25*(C8/C7)*C13 -> 308.69582 | D28: V
B29: Required Eal | C29: =MAX(C27:C28) -> 308.69582 | D29: V
B30: Pass / fail | C30: =IF(C29>C14,"fail","pass") -> pass
B33: RED670 - CT Requirement for Line Differential Protection
B34: Inputs
B35: Maximum internal close-in fault current Ikmax | C35: =Informationen!C6*1000 -> 29000 | D35: A
B36: Maximum external through-fault current Itmax | C36: =Informationen!D6*1000 -> 40000 | D36: A
B37: Results
B38: Ealreq equation 601: internal close-in fault | C38: =C35*C13*(C8/C7) -> 178.9111 | D38: V
B39: Ealreq equation 602: external through-fault | C39: =2*C36*C13*(C8/C7) -> 493.54786 | D39: V
B40: Required Eal | C40: =MAX(C38:C39) -> 493.54786 | D40: V
B41: Pass / fail | C41: =IF(C40>C14,"fail","pass") -> fail

Sheet 150 - 3
B1: =TEXT(Informationen!H7,"0")&" kV - Core "&TEXT(Informationen!A7,"0") -> 150 kV - Core 3
B2: General parameters
B3: Cable length | C3: =Informationen!Q7 -> 75 | D3: m
B4: Cable cross-section | C4: =Informationen!R7 -> 4 | D4: mm²
B5: Maximum temperature | C5: =Informationen!S7 -> 75 | D5: °C
B6: CT secondary resistance Rct | C6: =Informationen!N7 -> 7.5 | D6: Ohm
B7: CT rated primary current Ipr | C7: =Informationen!J7 -> 1250 | D7: A
B8: CT rated secondary current Isr | C8: =Informationen!K7 -> 1 | D8: A
B9: IED input burden SR | C9: =Informationen!O7 -> 0.02 | D9: VA
B10: Accuracy limiting factor ALF | C10: =Informationen!L7 -> 20
B11: Rated CT output Sn | C11: =Informationen!P7 -> 30 | D11: VA
B12: Intermediate calculations
B13: Total secondary burden | C13: =2*(0.0175*(C3/C4)*(1+0.00393*(C5-20)))+C6+(C9/C8^2) -> 8.3180984 | D13: Ohm
B14: Available CT Eal | C14: =C10*C8*(C6+C11/C8^2) -> 750 | D14: V
B17: RET670 - CT Requirement for Transformer Differential Protection
B18: Inputs
B19: Transformer Rating St | C19: =Informationen!G7 -> 310 | D19: MVA
B20: Nominal system voltage | C20: =Informationen!H7 -> 150 | D20: kV
B21: Transformer impedance | C21: =Informationen!I7 -> 18 | D21: %
B22: Current bypassing the transformer If | C22: =Informationen!F7 -> 8 | D22: A
B23: Intermediate calculations
B24: Transformer rated primary current Irt | C24: =C19*1000/(C20*SQRT(3)) -> 1193.1906 | D24: A
B25: Max. current through two main CTs and transformer Itf | C25: =C24*100/C21 -> 6628.8364 | D25: A
B26: Results
B27: Ealreq criterion 1: transformer rated current | C27: =30*C24*(C8/C7)*C13 -> 238.20184 | D27: V
B28: Ealreq criterion 2: through-fault current | C28: =2*C25*(C8/C7)*C13 -> 88.222902 | D28: V
B29: Required Eal | C29: =MAX(C27:C28) -> 238.20184 | D29: V
B30: Pass / fail | C30: =IF(C29>C14,"fail","pass") -> pass
B33: RED670 - CT Requirement for Line Differential Protection
B34: Inputs
B35: Maximum internal close-in fault current Ikmax | C35: =Informationen!C7*1000 -> 40000 | D35: A
B36: Maximum external through-fault current Itmax | C36: =Informationen!D7*1000 -> 40000 | D36: A
B37: Results
B38: Ealreq equation 601: internal close-in fault | C38: =C35*C13*(C8/C7) -> 266.17915 | D38: V
B39: Ealreq equation 602: external through-fault | C39: =2*C36*C13*(C8/C7) -> 532.3583 | D39: V
B40: Required Eal | C40: =MAX(C38:C39) -> 532.3583 | D40: V
B41: Pass / fail | C41: =IF(C40>C14,"fail","pass") -> pass

Sheet 150 - 4
B1: =TEXT(Informationen!H8,"0")&" kV - Core "&TEXT(Informationen!A8,"0") -> 150 kV - Core 4
B2: General parameters
B3: Cable length | C3: =Informationen!Q8 -> 70 | D3: m
B4: Cable cross-section | C4: =Informationen!R8 -> 4 | D4: mm²
B5: Maximum temperature | C5: =Informationen!S8 -> 75 | D5: °C
B6: CT secondary resistance Rct | C6: =Informationen!N8 -> 7.5 | D6: Ohm
B7: CT rated primary current Ipr | C7: =Informationen!J8 -> 1600 | D7: A
B8: CT rated secondary current Isr | C8: =Informationen!K8 -> 1 | D8: A
B9: IED input burden SR | C9: =Informationen!O8 -> 0.02 | D9: VA
B10: Accuracy limiting factor ALF | C10: =Informationen!L8 -> 40
B11: Rated CT output Sn | C11: =Informationen!P8 -> 10 | D11: VA
B12: Intermediate calculations
B13: Total secondary burden | C13: =2*(0.0175*(C3/C4)*(1+0.00393*(C5-20)))+C6+(C9/C8^2) -> 8.2648919 | D13: Ohm
B14: Available CT Eal | C14: =C10*C8*(C6+C11/C8^2) -> 700 | D14: V
B17: RET670 - CT Requirement for Transformer Differential Protection
B18: Inputs
B19: Transformer Rating St | C19: =Informationen!G8 -> 200 | D19: MVA
B20: Nominal system voltage | C20: =Informationen!H8 -> 150 | D20: kV
B21: Transformer impedance | C21: =Informationen!I8 -> 15 | D21: %
B22: Current bypassing the transformer If | C22: =Informationen!F8 -> 6 | D22: A
B23: Intermediate calculations
B24: Transformer rated primary current Irt | C24: =C19*1000/(C20*SQRT(3)) -> 769.80036 | D24: A
B25: Max. current through two main CTs and transformer Itf | C25: =C24*100/C21 -> 5132.0024 | D25: A
B26: Results
B27: Ealreq criterion 1: transformer rated current | C27: =30*C24*(C8/C7)*C13 -> 119.29344 | D27: V
B28: Ealreq criterion 2: through-fault current | C28: =2*C25*(C8/C7)*C13 -> 53.019306 | D28: V
B29: Required Eal | C29: =MAX(C27:C28) -> 119.29344 | D29: V
B30: Pass / fail | C30: =IF(C29>C14,"fail","pass") -> pass
B33: RED670 - CT Requirement for Line Differential Protection
B34: Inputs
B35: Maximum internal close-in fault current Ikmax | C35: =Informationen!C8*1000 -> 40000 | D35: A
B36: Maximum external through-fault current Itmax | C36: =Informationen!D8*1000 -> 40000 | D36: A
B37: Results
B38: Ealreq equation 601: internal close-in fault | C38: =C35*C13*(C8/C7) -> 206.6223 | D38: V
B39: Ealreq equation 602: external through-fault | C39: =2*C36*C13*(C8/C7) -> 413.24459 | D39: V
B40: Required Eal | C40: =MAX(C38:C39) -> 413.24459 | D40: V
B41: Pass / fail | C41: =IF(C40>C14,"fail","pass") -> pass

Sheet 33 - 1
B1: =TEXT(Informationen!H9,"0")&" kV - Core "&TEXT(Informationen!A9,"0") -> 33 kV - Core 1
B2: General parameters
B3: Cable length | C3: =Informationen!Q9 -> 13 | D3: m
B4: Cable cross-section | C4: =Informationen!R9 -> 1.5 | D4: mm²
B5: Maximum temperature | C5: =Informationen!S9 -> 75 | D5: °C
B6: CT secondary resistance Rct | C6: =Informationen!N9 -> 14 | D6: Ohm
B7: CT rated primary current Ipr | C7: =Informationen!J9 -> 2500 | D7: A
B8: CT rated secondary current Isr | C8: =Informationen!K9 -> 1 | D8: A
B9: IED input burden SR | C9: =Informationen!O9 -> 0.02 | D9: VA
B10: Accuracy limiting factor ALF | C10: =Informationen!L9 -> 20
B11: Rated CT output Sn | C11: =Informationen!P9 -> 15 | D11: VA
B12: Intermediate calculations
B13: Total secondary burden | C13: =2*(0.0175*(C3/C4)*(1+0.00393*(C5-20)))+C6+(C9/C8^2) -> 14.388899 | D13: Ohm
B14: Available CT Eal | C14: =C10*C8*(C6+C11/C8^2) -> 580 | D14: V
B17: RET670 - CT Requirement for Transformer Differential Protection
B18: Inputs
B19: Transformer Rating St | C19: =Informationen!G9 -> 110 | D19: MVA
B20: Nominal system voltage | C20: =Informationen!H9 -> 33 | D20: kV
B21: Transformer impedance | C21: =Informationen!I9 -> 12 | D21: %
B22: Current bypassing the transformer If | C22: =Informationen!F9 -> 16 | D22: A
B23: Intermediate calculations
B24: Transformer rated primary current Irt | C24: =C19*1000/(C20*SQRT(3)) -> 1924.5009 | D24: A
B25: Max. current through two main CTs and transformer Itf | C25: =C24*100/C21 -> 16037.507 | D25: A
B26: Results
B27: Ealreq criterion 1: transformer rated current | C27: =30*C24*(C8/C7)*C13 -> 332.29738 | D27: V
B28: Ealreq criterion 2: through-fault current | C28: =2*C25*(C8/C7)*C13 -> 184.60966 | D28: V
B29: Required Eal | C29: =MAX(C27:C28) -> 332.29738 | D29: V
B30: Pass / fail | C30: =IF(C29>C14,"fail","pass") -> pass
B33: RED670 - CT Requirement for Line Differential Protection
B34: Inputs
B35: Maximum internal close-in fault current Ikmax | C35: =Informationen!C9*1000 -> 31500 | D35: A
B36: Maximum external through-fault current Itmax | C36: =Informationen!D9*1000 -> 31500 | D36: A
B37: Results
B38: Ealreq equation 601: internal close-in fault | C38: =C35*C13*(C8/C7) -> 181.30013 | D38: V
B39: Ealreq equation 602: external through-fault | C39: =2*C36*C13*(C8/C7) -> 362.60025 | D39: V
B40: Required Eal | C40: =MAX(C38:C39) -> 362.60025 | D40: V
B41: Pass / fail | C41: =IF(C40>C14,"fail","pass") -> pass

Sheet 33 - 2
B1: =TEXT(Informationen!H10,"0")&" kV - Core "&TEXT(Informationen!A10,"0") -> 33 kV - Core 2
B2: General parameters
B3: Cable length | C3: =Informationen!Q10 -> 110 | D3: m
B4: Cable cross-section | C4: =Informationen!R10 -> 4 | D4: mm²
B5: Maximum temperature | C5: =Informationen!S10 -> 75 | D5: °C
B6: CT secondary resistance Rct | C6: =Informationen!N10 -> 20 | D6: Ohm
B7: CT rated primary current Ipr | C7: =Informationen!J10 -> 3000 | D7: A
B8: CT rated secondary current Isr | C8: =Informationen!K10 -> 1 | D8: A
B9: IED input burden SR | C9: =Informationen!O10 -> 0.02 | D9: VA
B10: Accuracy limiting factor ALF | C10: =Informationen!L10 -> 60
B11: Rated CT output Sn | C11: =Informationen!P10 -> 30 | D11: VA
B12: Intermediate calculations
B13: Total secondary burden | C13: =2*(0.0175*(C3/C4)*(1+0.00393*(C5-20)))+C6+(C9/C8^2) -> 21.190544 | D13: Ohm
B14: Available CT Eal | C14: =C10*C8*(C6+C11/C8^2) -> 3000 | D14: V
B17: RET670 - CT Requirement for Transformer Differential Protection
B18: Inputs
B19: Transformer Rating St | C19: =Informationen!G10 -> 175 | D19: MVA
B20: Nominal system voltage | C20: =Informationen!H10 -> 33 | D20: kV
B21: Transformer impedance | C21: =Informationen!I10 -> 12 | D21: %
B22: Current bypassing the transformer If | C22: =Informationen!F10 -> 29 | D22: A
B23: Intermediate calculations
B24: Transformer rated primary current Irt | C24: =C19*1000/(C20*SQRT(3)) -> 3061.706 | D24: A
B25: Max. current through two main CTs and transformer Itf | C25: =C24*100/C21 -> 25514.216 | D25: A
B26: Results
B27: Ealreq criterion 1: transformer rated current | C27: =30*C24*(C8/C7)*C13 -> 648.79216 | D27: V
B28: Ealreq criterion 2: through-fault current | C28: =2*C25*(C8/C7)*C13 -> 360.44009 | D28: V
B29: Required Eal | C29: =MAX(C27:C28) -> 648.79216 | D29: V
B30: Pass / fail | C30: =IF(C29>C14,"fail","pass") -> pass
B33: RED670 - CT Requirement for Line Differential Protection
B34: Inputs
B35: Maximum internal close-in fault current Ikmax | C35: =Informationen!C10*1000 -> 40000 | D35: A
B36: Maximum external through-fault current Itmax | C36: =Informationen!D10*1000 -> 40000 | D36: A
B37: Results
B38: Ealreq equation 601: internal close-in fault | C38: =C35*C13*(C8/C7) -> 282.54059 | D38: V
B39: Ealreq equation 602: external through-fault | C39: =2*C36*C13*(C8/C7) -> 565.08118 | D39: V
B40: Required Eal | C40: =MAX(C38:C39) -> 565.08118 | D40: V
B41: Pass / fail | C41: =IF(C40>C14,"fail","pass") -> pass

Sheet 33 - 3
B1: =TEXT(Informationen!H11,"0")&" kV - Core "&TEXT(Informationen!A11,"0") -> 33 kV - Core 3
B2: General parameters
B3: Cable length | C3: =Informationen!Q11 -> 55 | D3: m
B4: Cable cross-section | C4: =Informationen!R11 -> 4 | D4: mm²
B5: Maximum temperature | C5: =Informationen!S11 -> 75 | D5: °C
B6: CT secondary resistance Rct | C6: =Informationen!N11 -> 14 | D6: Ohm
B7: CT rated primary current Ipr | C7: =Informationen!J11 -> 2500 | D7: A
B8: CT rated secondary current Isr | C8: =Informationen!K11 -> 1 | D8: A
B9: IED input burden SR | C9: =Informationen!O11 -> 0.02 | D9: VA
B10: Accuracy limiting factor ALF | C10: =Informationen!L11 -> 20
B11: Rated CT output Sn | C11: =Informationen!P11 -> 20 | D11: VA
B12: Intermediate calculations
B13: Total secondary burden | C13: =2*(0.0175*(C3/C4)*(1+0.00393*(C5-20)))+C6+(C9/C8^2) -> 14.605272 | D13: Ohm
B14: Available CT Eal | C14: =C10*C8*(C6+C11/C8^2) -> 680 | D14: V
B17: RET670 - CT Requirement for Transformer Differential Protection
B18: Inputs
B19: Transformer Rating St | C19: =Informationen!G11 -> 155 | D19: MVA
B20: Nominal system voltage | C20: =Informationen!H11 -> 33 | D20: kV
B21: Transformer impedance | C21: =Informationen!I11 -> 12 | D21: %
B22: Current bypassing the transformer If | C22: =Informationen!F11 -> 25 | D22: A
B23: Intermediate calculations
B24: Transformer rated primary current Irt | C24: =C19*1000/(C20*SQRT(3)) -> 2711.7967 | D24: A
B25: Max. current through two main CTs and transformer Itf | C25: =C24*100/C21 -> 22598.306 | D25: A
B26: Results
B27: Ealreq criterion 1: transformer rated current | C27: =30*C24*(C8/C7)*C13 -> 475.27835 | D27: V
B28: Ealreq criterion 2: through-fault current | C28: =2*C25*(C8/C7)*C13 -> 264.04353 | D28: V
B29: Required Eal | C29: =MAX(C27:C28) -> 475.27835 | D29: V
B30: Pass / fail | C30: =IF(C29>C14,"fail","pass") -> pass
B33: RED670 - CT Requirement for Line Differential Protection
B34: Inputs
B35: Maximum internal close-in fault current Ikmax | C35: =Informationen!C11*1000 -> 29000 | D35: A
B36: Maximum external through-fault current Itmax | C36: =Informationen!D11*1000 -> 30000 | D36: A
B37: Results
B38: Ealreq equation 601: internal close-in fault | C38: =C35*C13*(C8/C7) -> 169.42116 | D38: V
B39: Ealreq equation 602: external through-fault | C39: =2*C36*C13*(C8/C7) -> 350.52653 | D39: V
B40: Required Eal | C40: =MAX(C38:C39) -> 350.52653 | D40: V
B41: Pass / fail | C41: =IF(C40>C14,"fail","pass") -> pass

Sheet 33 - 4
B1: =TEXT(Informationen!H12,"0")&" kV - Core "&TEXT(Informationen!A12,"0") -> 33 kV - Core 4
B2: General parameters
B3: Cable length | C3: =Informationen!Q12 -> 80 | D3: m
B4: Cable cross-section | C4: =Informationen!R12 -> 4 | D4: mm²
B5: Maximum temperature | C5: =Informationen!S12 -> 75 | D5: °C
B6: CT secondary resistance Rct | C6: =Informationen!N12 -> 18 | D6: Ohm
B7: CT rated primary current Ipr | C7: =Informationen!J12 -> 3000 | D7: A
B8: CT rated secondary current Isr | C8: =Informationen!K12 -> 1 | D8: A
B9: IED input burden SR | C9: =Informationen!O12 -> 0.02 | D9: VA
B10: Accuracy limiting factor ALF | C10: =Informationen!L12 -> 20
B11: Rated CT output Sn | C11: =Informationen!P12 -> 20 | D11: VA
B12: Intermediate calculations
B13: Total secondary burden | C13: =2*(0.0175*(C3/C4)*(1+0.00393*(C5-20)))+C6+(C9/C8^2) -> 18.871305 | D13: Ohm
B14: Available CT Eal | C14: =C10*C8*(C6+C11/C8^2) -> 760 | D14: V
B17: RET670 - CT Requirement for Transformer Differential Protection
B18: Inputs
B19: Transformer Rating St | C19: =Informationen!G12 -> 155 | D19: MVA
B20: Nominal system voltage | C20: =Informationen!H12 -> 33 | D20: kV
B21: Transformer impedance | C21: =Informationen!I12 -> 10 | D21: %
B22: Current bypassing the transformer If | C22: =Informationen!F12 -> 25 | D22: A
B23: Intermediate calculations
B24: Transformer rated primary current Irt | C24: =C19*1000/(C20*SQRT(3)) -> 2711.7967 | D24: A
B25: Max. current through two main CTs and transformer Itf | C25: =C24*100/C21 -> 27117.967 | D25: A
B26: Results
B27: Ealreq criterion 1: transformer rated current | C27: =30*C24*(C8/C7)*C13 -> 511.75143 | D27: V
B28: Ealreq criterion 2: through-fault current | C28: =2*C25*(C8/C7)*C13 -> 341.16762 | D28: V
B29: Required Eal | C29: =MAX(C27:C28) -> 511.75143 | D29: V
B30: Pass / fail | C30: =IF(C29>C14,"fail","pass") -> pass
B33: RED670 - CT Requirement for Line Differential Protection
B34: Inputs
B35: Maximum internal close-in fault current Ikmax | C35: =Informationen!C12*1000 -> 29000 | D35: A
B36: Maximum external through-fault current Itmax | C36: =Informationen!D12*1000 -> 29000 | D36: A
B37: Results
B38: Ealreq equation 601: internal close-in fault | C38: =C35*C13*(C8/C7) -> 182.42261 | D38: V
B39: Ealreq equation 602: external through-fault | C39: =2*C36*C13*(C8/C7) -> 364.84523 | D39: V
B40: Required Eal | C40: =MAX(C38:C39) -> 364.84523 | D40: V
B41: Pass / fail | C41: =IF(C40>C14,"fail","pass") -> pass

Sheet 33 - 5
B1: =TEXT(Informationen!H13,"0")&" kV - Core "&TEXT(Informationen!A13,"0") -> 33 kV - Core 5
B2: General parameters
B3: Cable length | C3: =Informationen!Q13 -> 40 | D3: m
B4: Cable cross-section | C4: =Informationen!R13 -> 2.5 | D4: mm²
B5: Maximum temperature | C5: =Informationen!S13 -> 75 | D5: °C
B6: CT secondary resistance Rct | C6: =Informationen!N13 -> 2 | D6: Ohm
B7: CT rated primary current Ipr | C7: =Informationen!J13 -> 500 | D7: A
B8: CT rated secondary current Isr | C8: =Informationen!K13 -> 1 | D8: A
B9: IED input burden SR | C9: =Informationen!O13 -> 0.02 | D9: VA
B10: Accuracy limiting factor ALF | C10: =Informationen!L13 -> 20
B11: Rated CT output Sn | C11: =Informationen!P13 -> 10 | D11: VA
B12: Intermediate calculations
B13: Total secondary burden | C13: =2*(0.0175*(C3/C4)*(1+0.00393*(C5-20)))+C6+(C9/C8^2) -> 2.701044 | D13: Ohm
B14: Available CT Eal | C14: =C10*C8*(C6+C11/C8^2) -> 240 | D14: V
B17: RET670 - CT Requirement for Transformer Differential Protection
B18: Inputs
B19: Transformer Rating St | C19: =Informationen!G13 -> 30 | D19: MVA
B20: Nominal system voltage | C20: =Informationen!H13 -> 33 | D20: kV
B21: Transformer impedance | C21: =Informationen!I13 -> 8 | D21: %
B22: Current bypassing the transformer If | C22: =Informationen!F13 -> 6 | D22: A
B23: Intermediate calculations
B24: Transformer rated primary current Irt | C24: =C19*1000/(C20*SQRT(3)) -> 524.86388 | D24: A
B25: Max. current through two main CTs and transformer Itf | C25: =C24*100/C21 -> 6560.7985 | D25: A
B26: Results
B27: Ealreq criterion 1: transformer rated current | C27: =30*C24*(C8/C7)*C13 -> 85.060826 | D27: V
B28: Ealreq criterion 2: through-fault current | C28: =2*C25*(C8/C7)*C13 -> 70.884022 | D28: V
B29: Required Eal | C29: =MAX(C27:C28) -> 85.060826 | D29: V
B30: Pass / fail | C30: =IF(C29>C14,"fail","pass") -> pass
B33: RED670 - CT Requirement for Line Differential Protection
B34: Inputs
B35: Maximum internal close-in fault current Ikmax | C35: =Informationen!C13*1000 -> 8400 | D35: A
B36: Maximum external through-fault current Itmax | C36: =Informationen!D13*1000 -> 8400 | D36: A
B37: Results
B38: Ealreq equation 601: internal close-in fault | C38: =C35*C13*(C8/C7) -> 45.377539 | D38: V
B39: Ealreq equation 602: external through-fault | C39: =2*C36*C13*(C8/C7) -> 90.755078 | D39: V
B40: Required Eal | C40: =MAX(C38:C39) -> 90.755078 | D40: V
B41: Pass / fail | C41: =IF(C40>C14,"fail","pass") -> pass

Sheet Results
A1: CT Calculation Results & SECP Comparison
A3: Calculation sheet | B3: Protection function | C3: Excel criterion 1 (V) | D3: Excel criterion 2 (V) | E3: Excel proposed Eal (V) | F3: Excel status | G3: SECP criterion 1 (V) | H3: SECP criterion 2 (V) | I3: SECP proposed Eal (V) | J3: SECP status | K3: Spalte1 | L3: Spalte 2 | M3: Excel / SECP (%) | N3: RL SECP (Ohm) | O3: RL Error (%)
A4: 220 - 1 | B4: Transformer differential | C4: ='220 - 1'!C27 -> 172.72266 | D4: ='220 - 1'!C28 -> 50.06454 | E4: ='220 - 1'!C14 -> 740 | F4: =IF(AND(C4<=E4,D4<=E4),"pass","fail") -> pass | G4: 195.6871 | H4: 56.7209 | I4: 740 | J4: =IF(AND(G4<=I4,H4<=I4),"pass","fail") -> pass | K4: =ResultsComparison[[#This Row],[SECP criterion 1 (V)]]/ResultsComparison[[#This Row],[Excel criterion 1 (V)]]*100-100 -> 13.295555 | L4: =ResultsComparison[[#This Row],[SECP criterion 2 (V)]]/ResultsComparison[[#This Row],[Excel criterion 2 (V)]]*100-100 -> 13.295557 | M4: =ResultsComparison[[#This Row],[Excel criterion 2 (V)]]/ResultsComparison[[#This Row],[SECP criterion 2 (V)]] -> 0.88264714 | N4: =N5 -> 1.0092 | O4: =O5 -> 0.053754726
A5: 220 - 1 | B5: Line differential | C5: ='220 - 1'!C38 -> 498.60738 | D5: ='220 - 1'!C39 -> 997.21477 | E5: ='220 - 1'!C14 -> 740 | F5: =IF(AND(C5<=E5,D5<=E5),"pass","fail") -> fail | G5: 501.825 | H5: 1003.65 | I5: 740 | J5: =IF(AND(G5<=I5,H5<=I5),"pass","fail") -> fail | K5: =ResultsComparison[[#This Row],[SECP criterion 1 (V)]]/ResultsComparison[[#This Row],[Excel criterion 1 (V)]]*100-100 -> 0.64532081 | L5: =ResultsComparison[[#This Row],[SECP criterion 2 (V)]]/ResultsComparison[[#This Row],[Excel criterion 2 (V)]]*100-100 -> 0.64532081 | M5: =ResultsComparison[[#This Row],[Excel criterion 2 (V)]]/ResultsComparison[[#This Row],[SECP criterion 2 (V)]] -> 0.99358817 | N5: ='220 - 1'!C13/ResultsComparison[[#This Row],[Excel / SECP (%)]] - ('220 - 1'!C6 + '220 - 1'!C9) -> 1.0092 | O5: =(ResultsComparison[[#This Row],[RL SECP (Ohm)]]/('220 - 1'!C13-'220 - 1'!C9-'220 - 1'!C6)-1) -> 0.053754726
A6: 150 - 1 | B6: Transformer differential | C6: ='150 - 1'!C27 -> 220.83624 | D6: ='150 - 1'!C28 -> 81.791201 | E6: ='150 - 1'!C14 -> 340 | F6: =IF(AND(C6<=E6,D6<=E6),"pass","fail") -> pass | G6: 242.7694 | H6: 89.9146 | I6: 340 | J6: =IF(AND(G6<=I6,H6<=I6),"pass","fail") -> pass | K6: =ResultsComparison[[#This Row],[SECP criterion 1 (V)]]/ResultsComparison[[#This Row],[Excel criterion 1 (V)]]*100-100 -> 9.9318652 | L6: =ResultsComparison[[#This Row],[SECP criterion 2 (V)]]/ResultsComparison[[#This Row],[Excel criterion 2 (V)]]*100-100 -> 9.9318743 | M6: =ResultsComparison[[#This Row],[Excel criterion 2 (V)]]/ResultsComparison[[#This Row],[SECP criterion 2 (V)]] -> 0.90965428 | N6: =N7 -> 0.7288 | O6: =O7 -> 0.053658343
A7: 150 - 1 | B7: Line differential | C7: ='150 - 1'!C38 -> 40.717698 | D7: ='150 - 1'!C39 -> 616.93482 | E7: ='150 - 1'!C14 -> 340 | F7: =IF(AND(C7<=E7,D7<=E7),"pass","fail") -> fail | G7: 40.9137 | H7: 619.904 | I7: 340 | J7: =IF(AND(G7<=I7,H7<=I7),"pass","fail") -> fail | K7: =ResultsComparison[[#This Row],[SECP criterion 1 (V)]]/ResultsComparison[[#This Row],[Excel criterion 1 (V)]]*100-100 -> 0.48136697 | L7: =ResultsComparison[[#This Row],[SECP criterion 2 (V)]]/ResultsComparison[[#This Row],[Excel criterion 2 (V)]]*100-100 -> 0.48127855 | M7: =ResultsComparison[[#This Row],[Excel criterion 2 (V)]]/ResultsComparison[[#This Row],[SECP criterion 2 (V)]] -> 0.99521027 | N7: ='150 - 1'!C13/ResultsComparison[[#This Row],[Excel / SECP (%)]] - ('150 - 1'!C6 + '150 - 1'!C9) -> 0.7288 | O7: =(ResultsComparison[[#This Row],[RL SECP (Ohm)]]/('150 - 1'!C13-'150 - 1'!C9-'150 - 1'!C6)-1) -> 0.053658343
A8: 150 - 2 | B8: Transformer differential | C8: ='150 - 2'!C27 -> 231.52187 | D8: ='150 - 2'!C28 -> 308.69582 | E8: ='150 - 2'!C14 -> 340 | F8: =IF(AND(C8<=E8,D8<=E8),"pass","fail") -> pass | G8: 254.5163 | H8: 339.3551 | I8: 340 | J8: =IF(AND(G8<=I8,H8<=I8),"pass","fail") -> pass | K8: =ResultsComparison[[#This Row],[SECP criterion 1 (V)]]/ResultsComparison[[#This Row],[Excel criterion 1 (V)]]*100-100 -> 9.9318624 | L8: =ResultsComparison[[#This Row],[SECP criterion 2 (V)]]/ResultsComparison[[#This Row],[Excel criterion 2 (V)]]*100-100 -> 9.9318732 | M8: =ResultsComparison[[#This Row],[Excel criterion 2 (V)]]/ResultsComparison[[#This Row],[SECP criterion 2 (V)]] -> 0.90965429 | N8: =N9 -> 0.7288 | O8: =O9 -> 0.053658343
A9: 150 - 2 | B9: Line differential | C9: ='150 - 2'!C38 -> 178.9111 | D9: ='150 - 2'!C39 -> 493.54786 | E9: ='150 - 2'!C14 -> 340 | F9: =IF(AND(C9<=E9,D9<=E9),"pass","fail") -> fail | G9: 179.7722 | H9: 495.9232 | I9: 340 | J9: =IF(AND(G9<=I9,H9<=I9),"pass","fail") -> fail | K9: =ResultsComparison[[#This Row],[SECP criterion 1 (V)]]/ResultsComparison[[#This Row],[Excel criterion 1 (V)]]*100-100 -> 0.48130091 | L9: =ResultsComparison[[#This Row],[SECP criterion 2 (V)]]/ResultsComparison[[#This Row],[Excel criterion 2 (V)]]*100-100 -> 0.48127855 | M9: =ResultsComparison[[#This Row],[Excel criterion 2 (V)]]/ResultsComparison[[#This Row],[SECP criterion 2 (V)]] -> 0.99521027 | N9: ='150 - 2'!C13/ResultsComparison[[#This Row],[Excel / SECP (%)]] - ('150 - 2'!C6 + '150 - 2'!C9) -> 0.7288 | O9: =(ResultsComparison[[#This Row],[RL SECP (Ohm)]]/('150 - 2'!C13-'150 - 2'!C9-'150 - 2'!C6)-1) -> 0.053658343
A10: 150 - 3 | B10: Transformer differential | C10: ='150 - 3'!C27 -> 238.20184 | D10: ='150 - 3'!C28 -> 88.222902 | E10: ='150 - 3'!C14 -> 750 | F10: =IF(AND(C10<=E10,D10<=E10),"pass","fail") -> pass | G10: 263.5138 | H10: 97.5977 | I10: 750 | J10: =IF(AND(G10<=I10,H10<=I10),"pass","fail") -> pass | K10: =ResultsComparison[[#This Row],[SECP criterion 1 (V)]]/ResultsComparison[[#This Row],[Excel criterion 1 (V)]]*100-100 -> 10.626267 | L10: =ResultsComparison[[#This Row],[SECP criterion 2 (V)]]/ResultsComparison[[#This Row],[Excel criterion 2 (V)]]*100-100 -> 10.626263 | M10: =ResultsComparison[[#This Row],[Excel criterion 2 (V)]]/ResultsComparison[[#This Row],[SECP criterion 2 (V)]] -> 0.90394448 | N10: =N11 -> 0.841 | O10: =O11 -> 0.053754726
A11: 150 - 3 | B11: Line differential | C11: ='150 - 3'!C38 -> 266.17915 | D11: ='150 - 3'!C39 -> 532.3583 | E11: ='150 - 3'!C14 -> 750 | F11: =IF(AND(C11<=E11,D11<=E11),"pass","fail") -> pass | G11: 267.552 | H11: 535.104 | I11: 750 | J11: =IF(AND(G11<=I11,H11<=I11),"pass","fail") -> pass | K11: =ResultsComparison[[#This Row],[SECP criterion 1 (V)]]/ResultsComparison[[#This Row],[Excel criterion 1 (V)]]*100-100 -> 0.51576166 | L11: =ResultsComparison[[#This Row],[SECP criterion 2 (V)]]/ResultsComparison[[#This Row],[Excel criterion 2 (V)]]*100-100 -> 0.51576166 | M11: =ResultsComparison[[#This Row],[Excel criterion 2 (V)]]/ResultsComparison[[#This Row],[SECP criterion 2 (V)]] -> 0.99486885 | N11: ='150 - 3'!C13/ResultsComparison[[#This Row],[Excel / SECP (%)]] - ('150 - 3'!C6 + '150 - 3'!C9) -> 0.841 | O11: =(ResultsComparison[[#This Row],[RL SECP (Ohm)]]/('150 - 3'!C13-'150 - 3'!C9-'150 - 3'!C6)-1) -> 0.053754726
A12: 150 - 4 | B12: Transformer differential | C12: ='150 - 4'!C27 -> 119.29344 | D12: ='150 - 4'!C28 -> 53.019306 | E12: ='150 - 4'!C14 -> 700 | F12: =IF(AND(C12<=E12,D12<=E12),"pass","fail") -> pass | G12: 131.2 | H12: 58.3111 | I12: 700 | J12: =IF(AND(G12<=I12,H12<=I12),"pass","fail") -> pass | K12: =ResultsComparison[[#This Row],[SECP criterion 1 (V)]]/ResultsComparison[[#This Row],[Excel criterion 1 (V)]]*100-100 -> 9.9809021 | L12: =ResultsComparison[[#This Row],[SECP criterion 2 (V)]]/ResultsComparison[[#This Row],[Excel criterion 2 (V)]]*100-100 -> 9.9808811 | M12: =ResultsComparison[[#This Row],[Excel criterion 2 (V)]]/ResultsComparison[[#This Row],[SECP criterion 2 (V)]] -> 0.90924894 | N12: =N13 -> 0.7849 | O12: =O13 -> 0.053709976
A13: 150 - 4 | B13: Line differential | C13: ='150 - 4'!C38 -> 206.6223 | D13: ='150 - 4'!C39 -> 413.24459 | E13: ='150 - 4'!C14 -> 700 | F13: =IF(AND(C13<=E13,D13<=E13),"pass","fail") -> pass | G13: 207.6225 | H13: 415.245 | I13: 700 | J13: =IF(AND(G13<=I13,H13<=I13),"pass","fail") -> pass | K13: =ResultsComparison[[#This Row],[SECP criterion 1 (V)]]/ResultsComparison[[#This Row],[Excel criterion 1 (V)]]*100-100 -> 0.48407318 | L13: =ResultsComparison[[#This Row],[SECP criterion 2 (V)]]/ResultsComparison[[#This Row],[Excel criterion 2 (V)]]*100-100 -> 0.48407318 | M13: =ResultsComparison[[#This Row],[Excel criterion 2 (V)]]/ResultsComparison[[#This Row],[SECP criterion 2 (V)]] -> 0.99518259 | N13: ='150 - 4'!C13/ResultsComparison[[#This Row],[Excel / SECP (%)]] - ('150 - 4'!C6 + '150 - 4'!C9) -> 0.7849 | O13: =(ResultsComparison[[#This Row],[RL SECP (Ohm)]]/('150 - 4'!C13-'150 - 4'!C9-'150 - 4'!C6)-1) -> 0.053709976
A14: 33 - 1 | B14: Transformer differential | C14: ='33 - 1'!C27 -> 332.29738 | D14: ='33 - 1'!C28 -> 184.60966 | E14: ='33 - 1'!C14 -> 580 | F14: =IF(AND(C14<=E14,D14<=E14),"pass","fail") -> pass | G14: 341.4496 | H14: 189.6942 | I14: 580 | J14: =IF(AND(G14<=I14,H14<=I14),"pass","fail") -> pass | K14: =ResultsComparison[[#This Row],[SECP criterion 1 (V)]]/ResultsComparison[[#This Row],[Excel criterion 1 (V)]]*100-100 -> 2.7542243 | L14: =ResultsComparison[[#This Row],[SECP criterion 2 (V)]]/ResultsComparison[[#This Row],[Excel criterion 2 (V)]]*100-100 -> 2.7542123 | M14: =ResultsComparison[[#This Row],[Excel criterion 2 (V)]]/ResultsComparison[[#This Row],[SECP criterion 2 (V)]] -> 0.97319611 | N14: =N15 -> 0.38259921 | O14: =O15 -> 0.037138564
A15: 33 - 1 | B15: Line differential | C15: ='33 - 1'!C38 -> 181.30013 | D15: ='33 - 1'!C39 -> 362.60025 | E15: ='33 - 1'!C14 -> 580 | F15: =IF(AND(C15<=E15,D15<=E15),"pass","fail") -> pass | G15: 181.4728 | H15: 362.9455 | I15: 580 | J15: =IF(AND(G15<=I15,H15<=I15),"pass","fail") -> pass | K15: =ResultsComparison[[#This Row],[SECP criterion 1 (V)]]/ResultsComparison[[#This Row],[Excel criterion 1 (V)]]*100-100 -> 0.09524246 | L15: =ResultsComparison[[#This Row],[SECP criterion 2 (V)]]/ResultsComparison[[#This Row],[Excel criterion 2 (V)]]*100-100 -> 0.095214882 | M15: =ResultsComparison[[#This Row],[Excel criterion 2 (V)]]/ResultsComparison[[#This Row],[SECP criterion 2 (V)]] -> 0.99904876 | N15: ='33 - 1'!C13/ResultsComparison[[#This Row],[Excel / SECP (%)]] - ('33 - 1'!C6 + '33 - 1'!C9) -> 0.38259921 | O15: =(ResultsComparison[[#This Row],[RL SECP (Ohm)]]/('33 - 1'!C13-'33 - 1'!C9-'33 - 1'!C6)-1) -> 0.037138564
A16: 33 - 2 | B16: Transformer differential | C16: ='33 - 2'!C27 -> 648.79216 | D16: ='33 - 2'!C28 -> 360.44009 | E16: ='33 - 2'!C14 -> 3000 | F16: =IF(AND(C16<=E16,D16<=E16),"pass","fail") -> pass | G16: 688.4797 | H16: 382.4887 | I16: 3000 | J16: =IF(AND(G16<=I16,H16<=I16),"pass","fail") -> pass | K16: =ResultsComparison[[#This Row],[SECP criterion 1 (V)]]/ResultsComparison[[#This Row],[Excel criterion 1 (V)]]*100-100 -> 6.1171419 | L16: =ResultsComparison[[#This Row],[SECP criterion 2 (V)]]/ResultsComparison[[#This Row],[Excel criterion 2 (V)]]*100-100 -> 6.1171357 | M16: =ResultsComparison[[#This Row],[Excel criterion 2 (V)]]/ResultsComparison[[#This Row],[SECP criterion 2 (V)]] -> 0.94235487 | N16: =N17 -> 1.2333988 | O16: =O17 -> 0.053696704
A17: 33 - 2 | B17: Line differential | C17: ='33 - 2'!C38 -> 282.54059 | D17: ='33 - 2'!C39 -> 565.08118 | E17: ='33 - 2'!C14 -> 3000 | F17: =IF(AND(C17<=E17,D17<=E17),"pass","fail") -> pass | G17: 283.3787 | H17: 566.7573 | I17: 3000 | J17: =IF(AND(G17<=I17,H17<=I17),"pass","fail") -> pass | K17: =ResultsComparison[[#This Row],[SECP criterion 1 (V)]]/ResultsComparison[[#This Row],[Excel criterion 1 (V)]]*100-100 -> 0.29663289 | L17: =ResultsComparison[[#This Row],[SECP criterion 2 (V)]]/ResultsComparison[[#This Row],[Excel criterion 2 (V)]]*100-100 -> 0.2966152 | M17: =ResultsComparison[[#This Row],[Excel criterion 2 (V)]]/ResultsComparison[[#This Row],[SECP criterion 2 (V)]] -> 0.99704262 | N17: ='33 - 2'!C13/ResultsComparison[[#This Row],[Excel / SECP (%)]] - ('33 - 2'!C6 + '33 - 2'!C9) -> 1.2333988 | O17: =(ResultsComparison[[#This Row],[RL SECP (Ohm)]]/('33 - 2'!C13-'33 - 2'!C9-'33 - 2'!C6)-1) -> 0.053696704
A18: 33 - 3 | B18: Transformer differential | C18: ='33 - 3'!C27 -> 475.27835 | D18: ='33 - 3'!C28 -> 264.04353 | E18: ='33 - 3'!C14 -> 680 | F18: =IF(AND(C18<=E18,D18<=E18),"pass","fail") -> pass | G18: 496.3694 | H18: 275.7608 | I18: 680 | J18: =IF(AND(G18<=I18,H18<=I18),"pass","fail") -> pass | K18: =ResultsComparison[[#This Row],[SECP criterion 1 (V)]]/ResultsComparison[[#This Row],[Excel criterion 1 (V)]]*100-100 -> 4.4376205 | L18: =ResultsComparison[[#This Row],[SECP criterion 2 (V)]]/ResultsComparison[[#This Row],[Excel criterion 2 (V)]]*100-100 -> 4.4376289 | M18: =ResultsComparison[[#This Row],[Excel criterion 2 (V)]]/ResultsComparison[[#This Row],[SECP criterion 2 (V)]] -> 0.95750929 | N18: =N19 -> 0.6167 | O18: =O19 -> 0.053697772
A19: 33 - 3 | B19: Line differential | C19: ='33 - 3'!C38 -> 169.42116 | D19: ='33 - 3'!C39 -> 350.52653 | E19: ='33 - 3'!C14 -> 680 | F19: =IF(AND(C19<=E19,D19<=E19),"pass","fail") -> pass | G19: 169.7857 | H19: 351.2808 | I19: 680 | J19: =IF(AND(G19<=I19,H19<=I19),"pass","fail") -> pass | K19: =ResultsComparison[[#This Row],[SECP criterion 1 (V)]]/ResultsComparison[[#This Row],[Excel criterion 1 (V)]]*100-100 -> 0.21516948 | L19: =ResultsComparison[[#This Row],[SECP criterion 2 (V)]]/ResultsComparison[[#This Row],[Excel criterion 2 (V)]]*100-100 -> 0.21518129 | M19: =ResultsComparison[[#This Row],[Excel criterion 2 (V)]]/ResultsComparison[[#This Row],[SECP criterion 2 (V)]] -> 0.99785281 | N19: ='33 - 3'!C13/ResultsComparison[[#This Row],[Excel / SECP (%)]] - ('33 - 3'!C6 + '33 - 3'!C9) -> 0.6167 | O19: =(ResultsComparison[[#This Row],[RL SECP (Ohm)]]/('33 - 3'!C13-'33 - 3'!C9-'33 - 3'!C6)-1) -> 0.053697772
A20: 33 - 4 | B20: Transformer differential | C20: ='33 - 4'!C27 -> 511.75143 | D20: ='33 - 4'!C28 -> 341.16762 | E20: ='33 - 4'!C14 -> 760 | F20: =IF(AND(C20<=E20,D20<=E20),"pass","fail") -> pass | G20: 537.3154 | H20: 358.2103 | I20: 760 | J20: =IF(AND(G20<=I20,H20<=I20),"pass","fail") -> pass | K20: =ResultsComparison[[#This Row],[SECP criterion 1 (V)]]/ResultsComparison[[#This Row],[Excel criterion 1 (V)]]*100-100 -> 4.9953881 | L20: =ResultsComparison[[#This Row],[SECP criterion 2 (V)]]/ResultsComparison[[#This Row],[Excel criterion 2 (V)]]*100-100 -> 4.9953979 | M20: =ResultsComparison[[#This Row],[Excel criterion 2 (V)]]/ResultsComparison[[#This Row],[SECP criterion 2 (V)]] -> 0.9524227 | N20: =N21 -> 0.89700172 | O20: =O21 -> 0.05367844
A21: 33 - 4 | B21: Line differential | C21: ='33 - 4'!C38 -> 182.42261 | D21: ='33 - 4'!C39 -> 364.84523 | E21: ='33 - 4'!C14 -> 760 | F21: =IF(AND(C21<=E21,D21<=E21),"pass","fail") -> pass | G21: 182.8643 | H21: 365.7287 | I21: 760 | J21: =IF(AND(G21<=I21,H21<=I21),"pass","fail") -> pass | K21: =ResultsComparison[[#This Row],[SECP criterion 1 (V)]]/ResultsComparison[[#This Row],[Excel criterion 1 (V)]]*100-100 -> 0.24212184 | L21: =ResultsComparison[[#This Row],[SECP criterion 2 (V)]]/ResultsComparison[[#This Row],[Excel criterion 2 (V)]]*100-100 -> 0.24214925 | M21: =ResultsComparison[[#This Row],[Excel criterion 2 (V)]]/ResultsComparison[[#This Row],[SECP criterion 2 (V)]] -> 0.99758436 | N21: ='33 - 4'!C13/ResultsComparison[[#This Row],[Excel / SECP (%)]] - ('33 - 4'!C6 + '33 - 4'!C9) -> 0.89700172 | O21: =(ResultsComparison[[#This Row],[RL SECP (Ohm)]]/('33 - 4'!C13-'33 - 4'!C9-'33 - 4'!C6)-1) -> 0.05367844
A22: 33 - 5 | B22: Transformer differential | C22: ='33 - 5'!C27 -> 85.060826 | D22: ='33 - 5'!C28 -> 70.884022 | E22: ='33 - 5'!C14 -> 240 | F22: =IF(AND(C22<=E22,D22<=E22),"pass","fail") -> pass | G22: 109.0184 | H22: 90.8487 | I22: 240 | J22: =IF(AND(G22<=I22,H22<=I22),"pass","fail") -> pass | K22: =ResultsComparison[[#This Row],[SECP criterion 1 (V)]]/ResultsComparison[[#This Row],[Excel criterion 1 (V)]]*100-100 -> 28.165226 | L22: =ResultsComparison[[#This Row],[SECP criterion 2 (V)]]/ResultsComparison[[#This Row],[Excel criterion 2 (V)]]*100-100 -> 28.165273 | M22: =ResultsComparison[[#This Row],[Excel criterion 2 (V)]]/ResultsComparison[[#This Row],[SECP criterion 2 (V)]] -> 0.78024256 | N22: =N23 -> 0.72089881 | O22: =O23 -> 0.058520168
A23: 33 - 5 | B23: Line differential | C23: ='33 - 5'!C38 -> 45.377539 | D23: ='33 - 5'!C39 -> 90.755078 | E23: ='33 - 5'!C14 -> 240 | F23: =IF(AND(C23<=E23,D23<=E23),"pass","fail") -> pass | G23: 46.0471 | H23: 92.0942 | I23: 240 | J23: =IF(AND(G23<=I23,H23<=I23),"pass","fail") -> pass | K23: =ResultsComparison[[#This Row],[SECP criterion 1 (V)]]/ResultsComparison[[#This Row],[Excel criterion 1 (V)]]*100-100 -> 1.4755335 | L23: =ResultsComparison[[#This Row],[SECP criterion 2 (V)]]/ResultsComparison[[#This Row],[Excel criterion 2 (V)]]*100-100 -> 1.4755335 | M23: =ResultsComparison[[#This Row],[Excel criterion 2 (V)]]/ResultsComparison[[#This Row],[SECP criterion 2 (V)]] -> 0.98545922 | N23: ='33 - 5'!C13/ResultsComparison[[#This Row],[Excel / SECP (%)]] - ('33 - 5'!C6 + '33 - 5'!C9) -> 0.72089881 | O23: =(ResultsComparison[[#This Row],[RL SECP (Ohm)]]/('33 - 5'!C13-'33 - 5'!C9-'33 - 5'!C6)-1) -> 0.058520168

Sheet Entscheidungsmatrix
A1: Decision Matrix – Transformer Differential Protection
A3: Data-Driven Metrics
A4: Number of transformer differential cases analyzed | B4: =COUNT(F50:F59) -> 10
A5: Minimum deviation between Excel and SECP | B5: =MIN(F50:F59) -> 0.026803887
A6: Average deviation between Excel and SECP | B6: =AVERAGE(F50:F59) -> 0.087912533
A7: Maximum deviation between Excel and SECP | B7: =MAX(F50:F59) -> 0.21975744
A8: Pass/fail agreement | B8: {=SUMPRODUCT(--(G50:G59=H50:H59))/COUNTA(G50:G59)} -> 1
A9: Direction of deviation | B9: SECP higher than Excel
A11: Weighted Quality Assessment
A12: Category | B12: Weight | C12: Score (0–4) | D12: Weighted Contribution | E12: Example Rationale | F12: Error Direction | G12: Action | H12: Status
A13: Correctness of the calculation method | B13: 0.2 | C13: 3 | D13: =IF(ISNUMBER(C13),B13*C13/4,0) -> 0.15
A14: Safety impact of deviations | B14: 0.2 | C14: 4 | D14: =IF(ISNUMBER(C14),B14*C14/4,0) -> 0.2
A15: Numerical accuracy of the results | B15: 0.2 | C15: 2 | D15: =IF(ISNUMBER(C15),B15*C15/4,0) -> 0.1
A16: Documentation and presentation quality | B16: 0.15 | C16: 1 | D16: =IF(ISNUMBER(C16),B16*C16/4,0) -> 0.0375
A17: Correctness of input processing | B17: 0.1 | C17: 3 | D17: =IF(ISNUMBER(C17),B17*C17/4,0) -> 0.075
A18: Consistency of the suitability decision | B18: 0.1 | C18: 4 | D18: =IF(ISNUMBER(C18),B18*C18/4,0) -> 0.1
A19: Traceability and reproducibility | B19: 0.05 | C19: 4 | D19: =IF(ISNUMBER(C19),B19*C19/4,0) -> 0.05
A20: Evaluated Weight | B20: =SUMIF(C13:C19,">=0",B13:B19) -> 1
A21: Normalized Overall Result | B21: =SUM(D13:D19)/B20 -> 0.7125
A24: Decision Matrix – Line Differential Protection
A26: Data-Driven Metrics
A27: Number of line differential cases analyzed | B27: =COUNT(F64:F73) -> 10
A28: Minimum deviation between Excel and SECP | B28: =MIN(F64:F73) -> 0.00095124309
A29: Average deviation between Excel and SECP | B29: =AVERAGE(F64:F73) -> 0.0048952102
A30: Maximum deviation between Excel and SECP | B30: =MAX(F64:F73) -> 0.014540781
A31: Pass/fail agreement | B31: {=SUMPRODUCT(--(G64:G73=H64:H73))/COUNTA(G64:G73)} -> 1
A32: Direction of deviation | B32: SECP higher than Excel
A34: Weighted Quality Assessment
A35: Category | B35: Weight | C35: Score (0–4) | D35: Weighted Contribution | E35: Example Rationale | F35: Error Direction | G35: Action | H35: Status
A36: Correctness of the calculation method | B36: 0.2 | C36: 4 | D36: =IF(ISNUMBER(C36),B36*C36/4,0) -> 0.2
A37: Safety impact of deviations | B37: 0.2 | C37: 4 | D37: =IF(ISNUMBER(C37),B37*C37/4,0) -> 0.2
A38: Numerical accuracy of the results | B38: 0.2 | C38: 3 | D38: =IF(ISNUMBER(C38),B38*C38/4,0) -> 0.15
A39: Documentation and presentation quality | B39: 0.15 | C39: 1 | D39: =IF(ISNUMBER(C39),B39*C39/4,0) -> 0.0375
A40: Correctness of input processing | B40: 0.1 | C40: 3 | D40: =IF(ISNUMBER(C40),B40*C40/4,0) -> 0.075
A41: Consistency of the suitability decision | B41: 0.1 | C41: 4 | D41: =IF(ISNUMBER(C41),B41*C41/4,0) -> 0.1
A42: Traceability and reproducibility | B42: 0.05 | C42: 4 | D42: =IF(ISNUMBER(C42),B42*C42/4,0) -> 0.05
A43: Evaluated Weight | B43: =SUMIF(C36:C42,">=0",B36:B42) -> 1
A44: Normalized Overall Result | B44: =SUM(D36:D42)/B43 -> 0.8125
A48: Data Basis – Transformer Differential Protection
A49: Calculation Sheet | B49: Excel Criterion 1 [V] | C49: Excel Criterion 2 [V] | D49: SECP Criterion 1 [V] | E49: SECP Criterion 2 [V] | F49: Deviation of Governing Criterion | G49: Excel Status | H49: SECP Status
...
